Workbook

Sheet Raw Data
A1: Code | B1: Badge Number | C1: Name(As per adhar card) | D1: Age | E1: Contact Number (WhatsApp)
A2: PPTW | B2: 1 | C2: Aachal Vinod Bhandari | D2: 15 | E2: 7720064326
A3: BB | B3: 2 | C3: Aanchal jain | D3: 26 | E3: 9399238454
A4: SC | B4: 3 | C4: Aangi | E4: 7405658429
A5: TT | B5: 4 | C5: Aarna | E5: 9904082060
A6: WID | B6: 5 | C6: Aarushi Bhandari | D6: 16 | E6: 9827637699
A7: PPTW | B7: 6 | C7: Aashvi chhajed | D7: 15 | E7: 7000496236
A8: BB | B8: 7 | C8: Aayushi Jain | D8: 19 | E8: 8815243359
A9: SC | B9: 8 | C9: Aayushi shah | D9: 25 | E9: 7506246643
A10: TT | B10: 9 | C10: Abhilasha Jain | D10: 34 | E10: 7089024861
A11: WID | B11: 10 | C11: Additi Solanki | D11: 22 | E11: 8667641257
A12: PPTW | B12: 11 | C12: Aditi | E12: 8104916757
A13: BB | B13: 12 | C13: Aditi Bhandari | E13: 9413351847
A14: SC | B14: 13 | C14: Aditi jain | D14: 22 | E14: 9039946841
A15: TT | B15: 14 | C15: Aishvi jain | D15: 26 | E15: 8109918270
A16: WID | B16: 15 | C16: Akshara Jain | D16: 16 | E16: 9584175407
A17: PPTW | B17: 16 | C17: Aksharachopra | D17: 17 | E17: 8253003710
A18: SC | B18: 17 | C18: Amisha Saklecha | D18: 25 | E18: 9399332675
A19: TT | B19: 18 | C19: Amita Mangesh Bora | D19: 32 | E19: 9422982899
A20: WID | B20: 19 | C20: Aneriben Manoj Kumar Shah | D20: 19 | E20: 9737943472
A21: PPTW | B21: 20 | C21: Anuja Romil Shah | D21: 40 | E21: 9390006566
A22: BB | B22: 21 | C22: Anushi Jain | D22: 24 | E22: 9131310377
A23: SC | B23: 22 | C23: Anushka Kataria | E23: 7000085196
A24: WID | B24: 23 | C24: Aradhana jain | D24: 31 | E24: 8965933229
A25: PPTW | B25: 24 | C25: Ariha Deep Shah | D25: 26 | E25: 9518509703
A26: BB | B26: 25 | C26: Arpita Jain | D26: 23 | E26: 9179352310
A27: SC | B27: 26 | C27: Arpita vanvat | D27: 35 | E27: 8103428286
A28: TT | B28: 27 | C28: Ashvi Jain | D28: 18 | E28: 8889055007
A29: WID | B29: 28 | C29: Avani Lodha | D29: 19 | E29: 9424044167
A30: BB | B30: 29 | C30: Avni jain | D30: 27 | E30: 6265328662
A31: SC | B31: 30 | C31: Ayushi chopra | D31: 24 | E31: 7089050778
A32: TT | B32: 31 | C32: B Ritu kothari | D32: 28 | E32: 8142214648
A33: WID | B33: 32 | C33: Bhaavee Chirag Doshi | D33: 13 | E33: 9552278383
A34: PPTW | B34: 33 | C34: Bhakti Jhaveri | D34: 40 | E34: 9833495207
A35: BB | B35: 34 | C35: Bhavana | D35: 33 | E35: 7667643221
... A42: WID | B42: 41 | C42: Charmi Doshi | D42: 35 | E42: 8898719999
A43: SC | B43: 42 | C43: Darshita Kakaria | E43: 9054322740
A44: TT | B44: 43 | C44: Deepali Shah | E44: 9323766181
A45: WID | B45: 44 | C45: Deshana Kuldip Shah | D45: 20 | E45: 8980189111
A46: BB | B46: 45 | C46: Devanshi hiran Mehta | D46: 38 | E46: 9482006740
...

Sheet Actual_Data
A1: Code | B1: Badge Number | C1: Name(As per adhar card) | D1: Age | E1: Contact Number (WhatsApp)
A2: PPTW | B2: 1 | C2: Aachal Vinod Bhandari | D2: 15 | E2: 7720064326
A3: BB | B3: 2 | C3: Aanchal jain | D3: 26 | E3: 9399238454
A4: SC | B4: 3 | C4: Aangi | E4: 7405658429
A5: TT | B5: 4 | C5: Aarna | E5: 9904082060
A6: WID | B6: 5 | C6: Aarushi Bhandari | D6: 16 | E6: 9827637699
A7: PPTW | B7: 6 | C7: Aashvi chhajed | D7: 15 | E7: 7000496236
A8: BB | B8: 7 | C8: Aayushi Jain | D8: 19 | E8: 8815243359
A9: SC | B9: 8 | C9: Aayushi shah | D9: 25 | E9: 7506246643
A10: TT | B10: 9 | C10: Abhilasha Jain | D10: 34 | E10: 7089024861
A11: WID | B11: 10 | C11: Additi Solanki | D11: 22 | E11: 8667641257
A12: PPTW | B12: 11 | C12: Aditi | E12: 8104916757
A13: BB | B13: 12 | C13: Aditi Bhandari | E13: 9413351847
A14: SC | B14: 13 | C14: Aditi jain | D14: 22 | E14: 9039946841
A15: TT | B15: 14 | C15: Aishvi jain | D15: 26 | E15: 8109918270
A16: WID | B16: 15 | C16: Akshara Jain | D16: 16 | E16: 9584175407
A17: PPTW | B17: 16 | C17: Aksharachopra | D17: 17 | E17: 8253003710
A18: SC | B18: 18 | C18: Amisha Saklecha | D18: 25 | E18: 9399332675
A19: TT | B19: 19 | C19: Amita Mangesh Bora | D19: 32 | E19: 9422982899
A20: WID | B20: 20 | C20: Aneriben Manoj Kumar Shah | D20: 19 | E20: 9737943472
A21: PPTW | B21: 21 | C21: Anuja Romil Shah | D21: 40 | E21: 9390006566
A22: BB | B22: 22 | C22: Anushi Jain | D22: 24 | E22: 9131310377
A23: SC | B23: 23 | C23: Anushka Kataria | E23: 7000085196
A24: WID | B24: 25 | C24: Aradhana jain | D24: 31 | E24: 8965933229
A25: PPTW | B25: 26 | C25: Ariha Deep Shah | D25: 26 | E25: 09518509703
A26: BB | B26: 27 | C26: Arpita Jain | D26: 23 | E26: 9179352310
A27: SC | B27: 28 | C27: Arpita vanvat | D27: 35 | E27: 8103428286
A28: TT | B28: 29 | C28: Ashvi Jain | D28: 18 | E28: 8889055007
A29: WID | B29: 30 | C29: Avani Lodha | D29: 19 | E29: 9424044167
A30: BB | B30: 32 | C30: Avni jain | D30: 27 | E30: 6265328662
A31: SC | B31: 33 | C31: Ayushi chopra | D31: 24 | E31: 7089050778
A32: TT | B32: 34 | C32: B Ritu kothari | D32: 28 | E32: 8142214648
A33: WID | B33: 35 | C33: Bhaavee Chirag Doshi | D33: 13 | E33: 9552278383
A34: PPTW | B34: 36 | C34: Bhakti Jhaveri | D34: 40 | E34: 9833495207
A35: BB | B35: 37 | C35: Bhavana | D35: 33 | E35: 7667643221
A36: SC | B36: 38 | C36: Bhavya | D36: 20 | E36: 9080505288
A37: TT | B37: 39 | C37: Bhumi chatter | D37: 15 | E37: 9575866660
... A42: WID | B42: 45 | C42: Charmi Doshi | D42: 35 | E42: 8898719999
A43: SC | B43: 48 | C43: Darshita Kakaria | E43: 9054322740
A44: TT | B44: 49 | C44: Deepali Shah | E44: 9323766181
...

Sheet Aaradhak_Details
A1: Timestamp | B1: Email address | C1: Name(As per adhar card) | D1: Code | E1: Badge Number | F1: Age | G1: Blood Group | H1: State/City | I1: Emergency Contact number | J1: Upload a Passport Size Photo | K1: Do you agree to the terms and conditions? | L1: Column 12
A2: 45996.505 | B2: ashvijain06@gmail.com | C2: Ashvi Jain | D2: TT | E2: 29 | F2: 18 | G2: AB +ve | H2: Indore, Madhya Pradesh | I2: 9425068194 | J2: https://drive.google.com/open?id=1Gzr-eY1XG6Yh53-0x80OZ0hCCHuTviea | K2: Yes, I do
A3: 45996.788 | B3: shahkrina2014@gmail.com | C3: Krina Shah | D3: SC | E3: 148 | F3: 18 | G3: B +ve | H3: Maharashtra/Mumbai | I3: 8169770863 | J3: https://drive.google.com/open?id=109wlIt98ft0VMeSRBk7uG8EjVjNr4gJv | K3: Yes, I do
A4: 45998.664 | B4: sonalbhandari78@gmail.com | C4: Aachal Vinod Bhandari | D4: PPTW | E4: 1 | F4: 15 | G4: B +ve | H4: Kolhapur Maharashtra | I4: 7720064326 | J4: https://drive.google.com/open?id=1leNh8vUSl2fpXLM86_zlju7kpjzTXg5j | K4: Yes, I do
A5: 45996.691 | B5: aanchaljain166@gmail.com | C5: Aanchal jain | D5: BB | E5: 2 | F5: 26 | G5: B +ve | H5: Pipliya mandi, District -Mandsaur, Madhya pradesh | I5: 9826990266 | J5: https://drive.google.com/open?id=1Pk-gWVTSSBzWIgAzVdacMhc8fBVmB7V4 | K5: Yes, I do
A6: 45996.537 | B6: Aangid7@gmail.com | C6: Aangi Dipeshbhai Doshi | D6: SC | E6: 3 | F6: 20 | G6: O +ve | H6: Ahmedabad | I6: 9825529797 | J6: https://drive.google.com/open?id=1xEgnxvO9TrHNEbL4s0w-tubtN8yBsdmP | K6: Yes, I do
A7: 46000.406 | B7: arpitchhajed0405@gmail.com | C7: Aashvi chhajed | D7: PPTW | E7: 6 | F7: 15 | G7: B +ve | H7: Khachrod | I7: 7000496236 | J7: https://drive.google.com/open?id=1ZoOhSBD3jdBKwbTbNeaFuNmZNrLi4cJy | K7: Yes, I do
A8: 45997.405 | B8: aayushi.jain4106@gmail.com | C8: Aayushi Jain | D8: BB | E8: 7 | F8: 19 | G8: AB +ve | H8: Madhya Pradesh | I8: 6261707675 | J8: https://drive.google.com/open?id=1yG_q-4vKPmnndSeO_MOv-hjSY8KdkWAx | K8: Yes, I do
A9: 46008.847 | B9: shahaayushi63@gmail.com | C9: Aayushi Shah | D9: SC | E9: 8 | F9: 25 | G9: B -ve | H9: Mumbai | I9: 9224190392 | J9: https://drive.google.com/open?id=1IsNNNfO3tG--Fg0fxMigbPaSt4Ess-l- | K9: Yes, I do
A10: 46000.515 | B10: jainrewinding@gmail.com | C10: Abhilasha | D10: TT | E10: 9 | F10: 34 | G10: AB +ve | H10: M.P./indore | I10: 9926124861 | J10: https://drive.google.com/open?id=1qr6viFOCwyAc02DBZ-C-fqLj0AzakiDq | K10: Yes, I do
A11: 46001.489 | B11: additisolanki10@gmail.com | C11: Additi Solanki | D11: WIB | E11: 10 | F11: 23 | G11: B +ve | H11: Chennai | I11: 9940478564 | J11: https://drive.google.com/open?id=1IVxjVwg4NlNzLptTJIjS-xDskZWlRg6t | K11: Yes, I do
A12: 45996.497 | B12: anshijain9876@gmail.com | C12: Aditi bhandari | D12: BB | E12: 12 | F12: 21 | G12: O +ve | H12: Chaumahla, Rajasthan | I12: 6260662123 | J12: https://drive.google.com/open?id=1oXPy6Zm6GhoIYSzNkxKURVQ7djkjD5og | K12: Yes, I do
A13: 46000.849 | B13: aditijain171202@gmail.com | C13: Aditi Bharat Jain | D13: PPTW | E13: 11 | F13: 23 | G13: A +ve | H13: Bhayandar, Mumbai | I13: 9324746678 | J13: https://drive.google.com/open?id=1EAB3FQz0Korngl0ssBPI_hipMXlbCNgh | K13: Yes, I do
... A18: 45996.53 | B18: aslodha11@gmail.com | C18: Amita Mangesh Bora | D18: TT | E18: 19 | F18: 32 | G18: B +ve | H18: Pune | I18: 9762808997 | J18: https://drive.google.com/open?id=1B7c4IO8U5tRyLDWb746lfEgxoK-jDl4V | K18: Yes, I do
A19: 46006.716 | B19: anerimshah06@gmail.com | C19: Aneri ben Manoj Kumar shah | D19: 395007 | E19: 20 | F19: 20 | G19: A +ve | H19: Surat | I19: 6380334389 | J19: https://drive.google.com/open?id=1Ke70RV3FarPfXPW4PmWACWj_CoIA8i4N | K19: Yes, I do
A20: 46019.417 | B20: sandeshjain242@gmail.com | C20: Ankita jain | D20: TT | E20: 451 | F20: 35 | G20: B +ve | H20: Indore | I20: 9981000715 | J20: https://drive.google.com/open?id=1wIgedSUkyP308HO_ys_G2weqFUo2daZH | K20: Yes, I do
A21: 45999.71 | B21: rxanuja@gmail.com | C21: Anuja Romil Shah | D21: PPTW | E21: 21 | F21: 42 | G21: B +ve | H21: Hyderabad | I21: 9825011862 | J21: https://drive.google.com/open?id=1ZPhSG_D5BL8eN1rbI3-IUd-dpGn8tdgO | K21: Yes, I do
A22: 45996.504 | B22: anushijain10@gmail.com | C22: Anushi Jain | D22: BB | E22: 22 | F22: 24 | G22: O +ve | H22: Madhya pradesh, Indore | I22: 9827071761 | J22: https://drive.google.com/open?id=1-dKLRDOlrHDu6S5FwVi65ajMnEUFQxXk | K22: Yes, I do
A23: 45997.445 | B23: anushkakataria26@gmail.com | C23: Anushka Kataria | D23: SC | E23: 23 | F23: 21 | G23: B +ve | H23: Ratlam,Madhya Pradesh | I23: 9425104131 | J23: https://drive.google.com/open?id=1MW-FmSb1BED-BzTiAKYND3h78d9UzyCi | K23: Yes, I do
A24: 45996.499 | B24: aradhanajain661994@gmail.com | C24: Aradhana jain | D24: WID | E24: 25 | F24: 31 | G24: B +ve | H24: Indore | I24: 7999992925 | J24: https://drive.google.com/open?id=1RUTBG-dunzR_1ITec3zSOmHz3rrl50QJ | K24: Yes, I do
A25: 46011.032 | B25: shaharchana28@gmail.com | C25: Archana Minesh Shah | D25: PPTW | E25: 428 | F25: 55 | G25: A +ve | H25: Mumbai | I25: 9870595409 | J25: https://drive.google.com/open?id=1O_6vS-YzKv96hUp__FOBpXoXOlcrhH56 | K25: Yes, I do
A26: 45996.58 | B26: shaharihad1999@gmail.com | C26: Ariha Deep Shah | D26: PPTW | E26: 26 | F26: 26 | G26: A +ve | H26: Pune | I26: 9011096550 | J26: https://drive.google.com/open?id=1UoCU_mvxPdga2KKiJOjJ6nmOWArJqR10 | K26: Yes, I do
A27: 45996.503 | B27: jainarpita56@gmail.com | C27: Arpita Jain | D27: AJ19 | E27: 27 | F27: 23 | G27: O +ve | H27: Madhya Pradesh/Mandsaur | I27: 9179352310 | J27: https://drive.google.com/open?id=14YwRH3CbaEyOm0I6W_0vyT-FDwqzBGoA | K27: Yes, I do
A28: 45999.903 | B28: arpita1vat249@gmail.com | C28: Arpita vanvat | D28: SC | E28: 28 | F28: 36 | G28: O +ve | H28: M.p. Khachrod | I28: 8770483294 | J28: https://drive.google.com/open?id=1WzoZcztCOECOdvrMIj6CdHBUMzOvXd5H | K28: Yes, I do
A29: 46009.464 | B29: ashita0206@gmail.com | C29: Ashita Dhariwal | D29: BB | E29: 407 | F29: 25 | G29: B +ve | H29: Indore | I29: 9424881377 | J29: https://drive.google.com/open?id=1EXWG06dnuu-oX7ZJJHxoRYJ0V6ymXMth | K29: Yes, I do
A30: 46010.778 | B30: ashvishah20@gmail.com | C30: Ashvi Amesh Shah | D30: TT | E30: 426 | F30: 21 | G30: A +ve | H30: Mumbai, Maharashtra | I30: 9322516954 | J30: https://drive.google.com/open?id=1kH7_tWsM2K39Tw1t8ly2i_Yq1cPAEgDc | K30: Yes, I do
A31: 46009.59 | B31: shahavani35@gmail.com | C31: Avani Vikram Shah | D31: TT | E31: 409 | F31: 28 | G31: B +ve | H31: Maharashtra/Bhiwandi | I31: 9321546930 | J31: https://drive.google.com/open?id=1DBSnLZ8YKTUqW2axAqjEDLFxsoKyvloZ | K31: Yes, I do
... A34: 46014.705 | B34: jainayushi3707@gmail.com | C34: Ayushi Jain | D34: SC | E34: 445 | F34: 24 | G34: B +ve | H34: Indore (Depalpur) | I34: 9926552626 | J34: https://drive.google.com/open?id=1SZpPc0A-sd5QRiA4IQLZhYcoGTJHWmzU | K34: Yes, I do
A35: 46004.505 | B35: aj4349741@gmail.com | C35: Ayushi Jain | D35: 391 | E35: 391 | F35: 18 | G35: O +ve | H35: Ujjain (Mp) | I35: 9993993381 | J35: https://drive.google.com/open?id=1tXoPeuEwCwZi6i8ODmxmJl8uyNzw3FVN | K35: Yes, I do
A36: 46007.774 | B36: jainmaya1995@gmail.com | C36: B Ritu kothari | D36: TT | E36: 34 | F36: 28 | G36: O +ve | H36: Anantapur | I36: 9381015186 | J36: https://drive.google.com/open?id=1mbUKXlvn8WyYxBGBy83PxmjJXvIOtb_Y | K36: Yes, I do
A37: 45996.71 | B37: drpoojacd1385@gmail.com | C37: Bhaavee Chirag Doshi | D37: WID | E37: 35 | F37: 13 | G37: O +ve | H37: Pune | I37: 9552278383 | J37: https://drive.google.com/open?id=1de-zzjrMLpbRjC3DgCls3MbFVoq8eB3U | K37: Yes, I do
A38: 45999.683 | B38: bhakti.jhaveri1985@gmail.com | C38: Bhakti Jhaveri | D38: PPTW | E38: 36 | F38: 40 | G38: B +ve | H38: Mumbai | I38: 8369232493 | J38: https://drive.google.com/open?id=1SXjn-AFGny_IPMt32vvw6rwfUNYXdhhg | K38: Yes, I do
A39: 46010.687 | B39: bhaktishah1312@gmail.com | C39: Bhakti shah | D39: WID | E39: 432 | F39: 22 | G39: O +ve | H39: Gujarat/Ahmedabad | I39: 7862919657 | J39: https://drive.google.com/open?id=11ZaONFphwaBLnHk4tIarGRLXAkuG4Elg | K39: Yes, I do
A40: 46005.534 | B40: jainbhawana805@gmail.com | C40: Bhavna Bhandari | D40: BB | E40: 392 | F40: 31 | G40: B +ve | H40: Chaumahla | I40: 9413805414 | J40: https://drive.google.com/open?id=1tqAWs0VY2goICihktdR7t9h3_RdfIYmj | K40: Yes, I do
A41: 46002.471 | B41: kushimehta344@gmail.com | C41: Bhavya | D41: Sc | E41: 38 | F41: 20 | G41: AB +ve | H41: Chennai | I41: 8015363385 | J41: https://drive.google.com/open?id=1aL6Yy6KD89Xfd5SLbmR6vYWzzw1xmRwi | K41: Yes, I do
A42: 46000.426 | B42: chatteradish@gmail.com | C42: Bhumi Chatter | D42: TT | E42: 39 | F42: 15 | G42: O +ve | H42: Khachrod Madhya pradesh | I42: 9584231441 | J42: https://drive.google.com/open?id=1Tol_266Slvk5pQKYAQgq1DQN5voYwq71 | K42: Yes, I do
A43: 46000.613 | B43: porwal.bhumi95@gmail.com | C43: Bhumika Jugal Porwal | D43: PPTW | E43: 41 | F43: 30 | G43: A +ve | H43: Pune , Maharashtra. | I43: 9561195563 | J43: https://drive.google.com/open?id=1ZlV2rkyubIs24FgJ2LMa0EqS4iFsfWOw | K43: Yes, I do
A44: 46001.324 | B44: shahutkersha384@gmail.com | C44: Bothara utkarsha abhay | D44: Sc | E44: 353 | F44: 20 | G44: O +ve | H44: Navsari | I44: 9712759705 | J44: https://drive.google.com/open?id=1Eb_1SOyXWLjLyY7kwDqMa42aLzJ0BpVq | K44: Yes, I do
A45: 45996.726 | B45: dhariwalcharmi2@gmail.com | C45: Charmi Dhariwal | D45: TT | E45: 44 | F45: 19 | G45: O +ve | H45: Jaora | I45: 9406635227 | J45: https://drive.google.com/open?id=1qWAoAxTtrKOuAgyPh8T1YVYXujFWnXen | K45: Yes, I do
A46: 46001.916 | B46: charmi.mehta2111@gmail.com | C46: Charmi Hardik Doshi | D46: WID | E46: 45 | F46: 35 | G46: O -ve | H46: Mumbai/ Maharashtra | I46: 9821127986 | J46: https://drive.google.com/open?id=1X6ZDOyiEmRJJcVto0apgHH0zVSr_gYe0 | K46: Yes, I do
...

Sheet ID Card Data
A1: Name(As per adhar card) | B1: Badge Number | C1: Age | D1: Blood Group | E1: Emergency Contact number
G3: The second sheet is named as Aaradhak details, and in this sheet, we will have the email address, the name as per their other card, the age, the blood group, and the emergency contact number

Sheet ID_Card_Output
A1: Name | B1: Badge Number | C1: Age | D1: Blood Group | E1: Emergency Contact Number | F1: Drive Photo Link
A2: =Actual_Data!C2 -> Aachal Vinod Bhandari | B2: =Actual_Data!B2 -> 1 | C2: =IFERROR(IF(VLOOKUP(B2,Aaradhak_Details!$E:$F,2,FALSE)<>"",VLOOKUP(B2,Aaradhak_Details!$E:$F,2,FALSE),Actual_Data!D2),Actual_Data!D2) -> 15 | D2: =IFERROR(VLOOKUP(B2,Aaradhak_Details!$E:$G,3,FALSE),"") -> B +ve | E2: =IFERROR(IF(VLOOKUP(B2,Aaradhak_Details!$E:$I,5,FALSE)<>"",VLOOKUP(B2,Aaradhak_Details!$E:$I,5,FALSE),Actual_Data!E2),Actual_Data!E2) -> 7720064326 | F2: {=IFERROR( INDEX(Aaradhak_Details!J:J, MATCH(B2, Aaradhak_Details!E:E, 0)), "" )} -> https://drive.google.com/open?id=1leNh8vUSl2fpXLM86_zlju7kpjzTXg5j | G2: {=IFERROR( XLOOKUP(A2, Aardhak_Details!B:B, Aardhak_Details!H:H), "" )}
A3: =Actual_Data!C3 -> Aanchal jain | B3: =Actual_Data!B3 -> 2 | C3: =IFERROR(IF(VLOOKUP(B3,Aaradhak_Details!$E:$F,2,FALSE)<>"",VLOOKUP(B3,Aaradhak_Details!$E:$F,2,FALSE),Actual_Data!D3),Actual_Data!D3) -> 26 | D3: =IFERROR(VLOOKUP(B3,Aaradhak_Details!$E:$G,3,FALSE),"") -> B +ve | E3: =IFERROR(IF(VLOOKUP(B3,Aaradhak_Details!$E:$I,5,FALSE)<>"",VLOOKUP(B3,Aaradhak_Details!$E:$I,5,FALSE),Actual_Data!E3),Actual_Data!E3) -> 9826990266 | F3: {=IFERROR( INDEX(Aaradhak_Details!J:J, MATCH(B3, Aaradhak_Details!E:E, 0)), "" )} -> https://drive.google.com/open?id=1Pk-gWVTSSBzWIgAzVdacMhc8fBVmB7V4
A4: =Actual_Data!C4 -> Aangi | B4: =Actual_Data!B4 -> 3 | C4: =IFERROR(IF(VLOOKUP(B4,Aaradhak_Details!$E:$F,2,FALSE)<>"",VLOOKUP(B4,Aaradhak_Details!$E:$F,2,FALSE),Actual_Data!D4),Actual_Data!D4) -> 20 | D4: =IFERROR(VLOOKUP(B4,Aaradhak_Details!$E:$G,3,FALSE),"") -> O +ve | E4: =IFERROR(IF(VLOOKUP(B4,Aaradhak_Details!$E:$I,5,FALSE)<>"",VLOOKUP(B4,Aaradhak_Details!$E:$I,5,FALSE),Actual_Data!E4),Actual_Data!E4) -> 9825529797 | F4: {=IFERROR( INDEX(Aaradhak_Details!J:J, MATCH(B4, Aaradhak_Details!E:E, 0)), "" )} -> https://drive.google.com/open?id=1xEgnxvO9TrHNEbL4s0w-tubtN8yBsdmP
A5: =Actual_Data!C5 -> Aarna | B5: =Actual_Data!B5 -> 4 | C5: =IFERROR(IF(VLOOKUP(B5,Aaradhak_Details!$E:$F,2,FALSE)<>"",VLOOKUP(B5,Aaradhak_Details!$E:$F,2,FALSE),Actual_Data!D5),Actual_Data!D5) -> 13 | D5: =IFERROR(VLOOKUP(B5,Aaradhak_Details!$E:$G,3,FALSE),"") -> A +ve | E5: =IFERROR(IF(VLOOKUP(B5,Aaradhak_Details!$E:$I,5,FALSE)<>"",VLOOKUP(B5,Aaradhak_Details!$E:$I,5,FALSE),Actual_Data!E5),Actual_Data!E5) -> 9904082060 | F5: {=IFERROR( INDEX(Aaradhak_Details!J:J, MATCH(B5, Aaradhak_Details!E:E, 0)), "" )} -> https://drive.google.com/open?id=1HCpgRtQSMj4AUEuv7jvRMQbRRajWdQZ4
A6: =Actual_Data!C6 -> Aarushi Bhandari | B6: =Actual_Data!B6 -> 5 | C6: =IFERROR(IF(VLOOKUP(B6,Aaradhak_Details!$E:$F,2,FALSE)<>"",VLOOKUP(B6,Aaradhak_Details!$E:$F,2,FALSE),Actual_Data!D6),Actual_Data!D6) -> 21 | D6: =IFERROR(VLOOKUP(B6,Aaradhak_Details!$E:$G,3,FALSE),"") -> B +ve | E6: =IFERROR(IF(VLOOKUP(B6,Aaradhak_Details!$E:$I,5,FALSE)<>"",VLOOKUP(B6,Aaradhak_Details!$E:$I,5,FALSE),Actual_Data!E6),Actual_Data!E6) -> 7898954083 | F6: {=IFERROR( INDEX(Aaradhak_Details!J:J, MATCH(B6, Aaradhak_Details!E:E, 0)), "" )} -> https://drive.google.com/open?id=1GNICRNBvoOyF2dC_2G-aSg9ISikON033
A7: =Actual_Data!C7 -> Aashvi chhajed | B7: =Actual_Data!B7 -> 6 | C7: =IFERROR(IF(VLOOKUP(B7,Aaradhak_Details!$E:$F,2,FALSE)<>"",VLOOKUP(B7,Aaradhak_Details!$E:$F,2,FALSE),Actual_Data!D7),Actual_Data!D7) -> 15 | D7: =IFERROR(VLOOKUP(B7,Aaradhak_Details!$E:$G,3,FALSE),"") -> B +ve | E7: =IFERROR(IF(VLOOKUP(B7,Aaradhak_Details!$E:$I,5,FALSE)<>"",VLOOKUP(B7,Aaradhak_Details!$E:$I,5,FALSE),Actual_Data!E7),Actual_Data!E7) -> 7000496236 | F7: {=IFERROR( INDEX(Aaradhak_Details!J:J, MATCH(B7, Aaradhak_Details!E:E, 0)), "" )} -> https://drive.google.com/open?id=1ZoOhSBD3jdBKwbTbNeaFuNmZNrLi4cJy
A8: =Actual_Data!C8 -> Aayushi Jain | B8: =Actual_Data!B8 -> 7 | C8: =IFERROR(IF(VLOOKUP(B8,Aaradhak_Details!$E:$F,2,FALSE)<>"",VLOOKUP(B8,Aaradhak_Details!$E:$F,2,FALSE),Actual_Data!D8),Actual_Data!D8) -> 19 | D8: =IFERROR(VLOOKUP(B8,Aaradhak_Details!$E:$G,3,FALSE),"") -> AB +ve | E8: =IFERROR(IF(VLOOKUP(B8,Aaradhak_Details!$E:$I,5,FALSE)<>"",VLOOKUP(B8,Aaradhak_Details!$E:$I,5,FALSE),Actual_Data!E8),Actual_Data!E8) -> 6261707675 | F8: {=IFERROR( INDEX(Aaradhak_Details!J:J, MATCH(B8, Aaradhak_Details!E:E, 0)), "" )} -> https://drive.google.com/open?id=1yG_q-4vKPmnndSeO_MOv-hjSY8KdkWAx
A9: =Actual_Data!C9 -> Aayushi shah | B9: =Actual_Data!B9 -> 8 | C9: =IFERROR(IF(VLOOKUP(B9,Aaradhak_Details!$E:$F,2,FALSE)<>"",VLOOKUP(B9,Aaradhak_Details!$E:$F,2,FALSE),Actual_Data!D9),Actual_Data!D9) -> 25 | D9: =IFERROR(VLOOKUP(B9,Aaradhak_Details!$E:$G,3,FALSE),"") -> B -ve | E9: =IFERROR(IF(VLOOKUP(B9,Aaradhak_Details!$E:$I,5,FALSE)<>"",VLOOKUP(B9,Aaradhak_Details!$E:$I,5,FALSE),Actual_Data!E9),Actual_Data!E9) -> 9224190392 | F9: {=IFERROR( INDEX(Aaradhak_Details!J:J, MATCH(B9, Aaradhak_Details!E:E, 0)), "" )} -> https://drive.google.com/open?id=1IsNNNfO3tG--Fg0fxMigbPaSt4Ess-l-
A10: =Actual_Data!C10 -> Abhilasha Jain | B10: =Actual_Data!B10 -> 9 | C10: =IFERROR(IF(VLOOKUP(B10,Aaradhak_Details!$E:$F,2,FALSE)<>"",VLOOKUP(B10,Aaradhak_Details!$E:$F,2,FALSE),Actual_Data!D10),Actual_Data!D10) -> 34 | D10: =IFERROR(VLOOKUP(B10,Aaradhak_Details!$E:$G,3,FALSE),"") -> AB +ve | E10: =IFERROR(IF(VLOOKUP(B10,Aaradhak_Details!$E:$I,5,FALSE)<>"",VLOOKUP(B10,Aaradhak_Details!$E:$I,5,FALSE),Actual_Data!E10),Actual_Data!E10) -> 9926124861 | F10: {=IFERROR( INDEX(Aaradhak_Details!J:J, MATCH(B10, Aaradhak_Details!E:E, 0)), "" )} -> https://drive.google.com/open?id=1qr6viFOCwyAc02DBZ-C-fqLj0AzakiDq
A11: =Actual_Data!C11 -> Additi Solanki | B11: =Actual_Data!B11 -> 10 | C11: =IFERROR(IF(VLOOKUP(B11,Aaradhak_Details!$E:$F,2,FALSE)<>"",VLOOKUP(B11,Aaradhak_Details!$E:$F,2,FALSE),Actual_Data!D11),Actual_Data!D11) -> 23 | D11: =IFERROR(VLOOKUP(B11,Aaradhak_Details!$E:$G,3,FALSE),"") -> B +ve | E11: =IFERROR(IF(VLOOKUP(B11,Aaradhak_Details!$E:$I,5,FALSE)<>"",VLOOKUP(B11,Aaradhak_Details!$E:$I,5,FALSE),Actual_Data!E11),Actual_Data!E11) -> 9940478564 | F11: {=IFERROR( INDEX(Aaradhak_Details!J:J, MATCH(B11, Aaradhak_Details!E:E, 0)), "" )} -> https://drive.google.com/open?id=1IVxjVwg4NlNzLptTJIjS-xDskZWlRg6t
A12: =Actual_Data!C12 -> Aditi | B12: =Actual_Data!B12 -> 11 | C12: =IFERROR(IF(VLOOKUP(B12,Aaradhak_Details!$E:$F,2,FALSE)<>"",VLOOKUP(B12,Aaradhak_Details!$E:$F,2,FALSE),Actual_Data!D12),Actual_Data!D12) -> 23 | D12: =IFERROR(VLOOKUP(B12,Aaradhak_Details!$E:$G,3,FALSE),"") -> A +ve | E12: =IFERROR(IF(VLOOKUP(B12,Aaradhak_Details!$E:$I,5,FALSE)<>"",VLOOKUP(B12,Aaradhak_Details!$E:$I,5,FALSE),Actual_Data!E12),Actual_Data!E12) -> 9324746678 | F12: {=IFERROR( INDEX(Aaradhak_Details!J:J, MATCH(B12, Aaradhak_Details!E:E, 0)), "" )} -> https://drive.google.com/open?id=1EAB3FQz0Korngl0ssBPI_hipMXlbCNgh
A13: =Actual_Data!C13 -> Aditi Bhandari | B13: =Actual_Data!B13 -> 12 | C13: =IFERROR(IF(VLOOKUP(B13,Aaradhak_Details!$E:$F,2,FALSE)<>"",VLOOKUP(B13,Aaradhak_Details!$E:$F,2,FALSE),Actual_Data!D13),Actual_Data!D13) -> 21 | D13: =IFERROR(VLOOKUP(B13,Aaradhak_Details!$E:$G,3,FALSE),"") -> O +ve | E13: =IFERROR(IF(VLOOKUP(B13,Aaradhak_Details!$E:$I,5,FALSE)<>"",VLOOKUP(B13,Aaradhak_Details!$E:$I,5,FALSE),Actual_Data!E13),Actual_Data!E13) -> 6260662123 | F13: {=IFERROR( INDEX(Aaradhak_Details!J:J, MATCH(B13, Aaradhak_Details!E:E, 0)), "" )} -> https://drive.google.com/open?id=1oXPy6Zm6GhoIYSzNkxKURVQ7djkjD5og
A14: =Actual_Data!C14 -> Aditi jain | B14: =Actual_Data!B14 -> 13 | C14: =IFERROR(IF(VLOOKUP(B14,Aaradhak_Details!$E:$F,2,FALSE)<>"",VLOOKUP(B14,Aaradhak_Details!$E:$F,2,FALSE),Actual_Data!D14),Actual_Data!D14) -> 22 | D14: =IFERROR(VLOOKUP(B14,Aaradhak_Details!$E:$G,3,FALSE),"") -> A +ve | E14: =IFERROR(IF(VLOOKUP(B14,Aaradhak_Details!$E:$I,5,FALSE)<>"",VLOOKUP(B14,Aaradhak_Details!$E:$I,5,FALSE),Actual_Data!E14),Actual_Data!E14) -> 8435695030 | F14: {=IFERROR( INDEX(Aaradhak_Details!J:J, MATCH(B14, Aaradhak_Details!E:E, 0)), "" )} -> https://drive.google.com/open?id=1fsYeyvPM0MDktd5Fgn3GWHAhAUF-pmPW
... A418: =Actual_Data!C418 -> Moksha Shah | B418: =Actual_Data!B418 -> 475 | C418: =IFERROR(IF(VLOOKUP(B418,Aaradhak_Details!$E:$F,2,FALSE)<>"",VLOOKUP(B418,Aaradhak_Details!$E:$F,2,FALSE),Actual_Data!D418),Actual_Data!D418) -> 23 | D418: =IFERROR(VLOOKUP(B418,Aaradhak_Details!$E:$G,3,FALSE),"") -> AB +ve | E418: =IFERROR(IF(VLOOKUP(B418,Aaradhak_Details!$E:$I,5,FALSE)<>"",VLOOKUP(B418,Aaradhak_Details!$E:$I,5,FALSE),Actual_Data!E418),Actual_Data!E418) -> 9427608729 | F418: {=IFERROR( INDEX(Aaradhak_Details!J:J, MATCH(B418, Aaradhak_Details!E:E, 0)), "" )} -> https://drive.google.com/open?id=1WDaZ3bK-waxZUJWNPp7IbYuV3Ww7yvt3
A419: =Actual_Data!C419
A420: =Actual_Data!C420
A421: =Actual_Data!C421
A422: =Actual_Data!C422
A423: =Actual_Data!C423
A424: =Actual_Data!C424
A425: =Actual_Data!C425
A426: =Actual_Data!C426
A427: =Actual_Data!C427
A428: =Actual_Data!C428
A429: =Actual_Data!C429
A430: =Actual_Data!C430
... A441: =Actual_Data!C441

Sheet Final Data
A1: Name | B1: Badge Number | C1: Age | D1: Blood Group | E1: Emergency Contact Number | F1: Drive Photo Link
A2: Aachal Vinod Bhandari | B2: {=SEQUENCE(400,1)} -> 1 | C2: 15 | D2: B +ve | E2: 7720064326 | F2: https://drive.google.com/open?id=1leNh8vUSl2fpXLM86_zlju7kpjzTXg5j
A3: Aanchal jain | B3: 2 | C3: 26 | D3: B +ve | E3: 9826990266 | F3: https://drive.google.com/open?id=1Pk-gWVTSSBzWIgAzVdacMhc8fBVmB7V4
A4: Aangi | B4: 3 | C4: 20 | D4: O +ve | E4: 9825529797 | F4: https://drive.google.com/open?id=1xEgnxvO9TrHNEbL4s0w-tubtN8yBsdmP
A5: Aarna | B5: 4 | C5: 13 | D5: A +ve | E5: 9904082060 | F5: https://drive.google.com/open?id=1HCpgRtQSMj4AUEuv7jvRMQbRRajWdQZ4
A6: Aarushi Bhandari | B6: 5 | C6: 21 | D6: B +ve | E6: 7898954083 | F6: https://drive.google.com/open?id=1GNICRNBvoOyF2dC_2G-aSg9ISikON033
A7: Aashvi chhajed | B7: 6 | C7: 15 | D7: B +ve | E7: 7000496236 | F7: https://drive.google.com/open?id=1ZoOhSBD3jdBKwbTbNeaFuNmZNrLi4cJy
A8: Aayushi Jain | B8: 7 | C8: 19 | D8: AB +ve | E8: 6261707675 | F8: https://drive.google.com/open?id=1yG_q-4vKPmnndSeO_MOv-hjSY8KdkWAx
A9: Aayushi shah | B9: 8 | C9: 25 | D9: B -ve | E9: 9224190392 | F9: https://drive.google.com/open?id=1IsNNNfO3tG--Fg0fxMigbPaSt4Ess-l-
A10: Abhilasha Jain | B10: 9 | C10: 34 | D10: AB +ve | E10: 9926124861 | F10: https://drive.google.com/open?id=1qr6viFOCwyAc02DBZ-C-fqLj0AzakiDq
A11: Additi Solanki | B11: 10 | C11: 23 | D11: B +ve | E11: 9940478564 | F11: https://drive.google.com/open?id=1IVxjVwg4NlNzLptTJIjS-xDskZWlRg6t
A12: Aditi | B12: 11 | C12: 23 | D12: A +ve | E12: 9324746678 | F12: https://drive.google.com/open?id=1EAB3FQz0Korngl0ssBPI_hipMXlbCNgh
A13: Aditi Bhandari | B13: 12 | C13: 21 | D13: O +ve | E13: 6260662123 | F13: https://drive.google.com/open?id=1oXPy6Zm6GhoIYSzNkxKURVQ7djkjD5og
A14: Aditi jain | B14: 13 | C14: 22 | D14: A +ve | E14: 8435695030 | F14: https://drive.google.com/open?id=1fsYeyvPM0MDktd5Fgn3GWHAhAUF-pmPW
A15: Aishvi jain | B15: 14 | C15: 26 | D15: B +ve | E15: 9893618270 | F15: https://drive.google.com/open?id=11HDfHGWyVyRZ6cfWoSFilBJQ_vpyMVF8
A16: Akshara Jain | B16: 15 | C16: 16 | E16: 9584175407
A17: Aksharachopra | B17: 16 | C17: 17 | D17: O +ve | E17: 9300638289 | F17: https://drive.google.com/open?id=1qjGe0s8uGO2FjUCr_Ae2YluvlxGU-yoO
A18: Amisha Saklecha | B18: 17 | C18: 25 | D18: A +ve | E18: 9713410009 | F18: https://drive.google.com/open?id=1pGnRcx4f1hPxHK0dkzJrs7ghuXPZyB11
A19: Amita Mangesh Bora | B19: 18 | C19: 32 | D19: B +ve | E19: 9762808997 | F19: https://drive.google.com/open?id=1B7c4IO8U5tRyLDWb746lfEgxoK-jDl4V
A20: Aneriben Manoj Kumar Shah | B20: 19 | C20: 20 | D20: A +ve | E20: 6380334389 | F20: https://drive.google.com/open?id=1Ke70RV3FarPfXPW4PmWACWj_CoIA8i4N
A21: Anuja Romil Shah | B21: 20 | C21: 42 | D21: B +ve | E21: 9825011862 | F21: https://drive.google.com/open?id=1ZPhSG_D5BL8eN1rbI3-IUd-dpGn8tdgO
A22: Anushi Jain | B22: 21 | C22: 24 | D22: O +ve | E22: 9827071761 | F22: https://drive.google.com/open?id=1-dKLRDOlrHDu6S5FwVi65ajMnEUFQxXk
A23: Anushka Kataria | B23: 22 | C23: 21 | D23: B +ve | E23: 9425104131 | F23: https://drive.google.com/open?id=1MW-FmSb1BED-BzTiAKYND3h78d9UzyCi
A24: Aradhana jain | B24: 23 | C24: 31 | D24: B +ve | E24: 7999992925 | F24: https://drive.google.com/open?id=1RUTBG-dunzR_1ITec3zSOmHz3rrl50QJ
A25: Ariha Deep Shah | B25: 24 | C25: 26 | D25: A +ve | E25: 9011096550 | F25: https://drive.google.com/open?id=1UoCU_mvxPdga2KKiJOjJ6nmOWArJqR10
A26: Arpita Jain | B26: 25 | C26: 23 | D26: O +ve | E26: 9179352310 | F26: https://drive.google.com/open?id=14YwRH3CbaEyOm0I6W_0vyT-FDwqzBGoA
A27: Arpita vanvat | B27: 26 | C27: 36 | D27: O +ve | E27: 8770483294 | F27: https://drive.google.com/open?id=1WzoZcztCOECOdvrMIj6CdHBUMzOvXd5H
A28: Ashvi Jain | B28: 27 | C28: 18 | D28: AB +ve | E28: 9425068194 | F28: https://drive.google.com/open?id=1Gzr-eY1XG6Yh53-0x80OZ0hCCHuTviea
A29: Avani Lodha | B29: 28 | C29: 19 | E29: 9424044167
A30: Avni jain | B30: 29 | C30: 27 | D30: B +ve | E30: 7771906579 | F30: https://drive.google.com/open?id=1EI6cBj0MJs2Z2a84cigzSX7mh8TzeshT
A31: Ayushi chopra | B31: 30 | C31: 24 | D31: O +ve | E31: 7354054343 | F31: https://drive.google.com/open?id=14wcqcgIGR0Ogh4UE59Vti2Yb5PU8SOPF
A32: B Ritu kothari | B32: 31 | C32: 28 | D32: O +ve | E32: 9381015186 | F32: https://drive.google.com/open?id=1mbUKXlvn8WyYxBGBy83PxmjJXvIOtb_Y
A33: Bhaavee Chirag Doshi | B33: 32 | C33: 13 | D33: O +ve | E33: 9552278383 | F33: https://drive.google.com/open?id=1de-zzjrMLpbRjC3DgCls3MbFVoq8eB3U
A34: Bhakti Jhaveri | B34: 33 | C34: 40 | D34: B +ve | E34: 8369232493 | F34: https://drive.google.com/open?id=1SXjn-AFGny_IPMt32vvw6rwfUNYXdhhg
A35: Bhavana | B35: 34 | C35: 33 | E35: 7667643221
A36: Bhavya | B36: 35 | C36: 20 | D36: AB +ve | E36: 8015363385 | F36: https://drive.google.com/open?id=1aL6Yy6KD89Xfd5SLbmR6vYWzzw1xmRwi
A37: Bhumi chatter | B37: 36 | C37: 15 | D37: O +ve | E37: 9584231441 | F37: https://drive.google.com/open?id=1Tol_266Slvk5pQKYAQgq1DQN5voYwq71
A38: Bhumi Umesh Gadiya | B38: 37 | C38: 18 | D38: O +ve | E38: 7620396824 | F38: https://drive.google.com/open?id=1J0MuRe-MCw3zgySp4uabWGaqNVhg3J4r
A39: Bhumika | B39: 38 | C39: 30 | D39: A +ve | E39: 9561195563 | F39: https://drive.google.com/open?id=1ZlV2rkyubIs24FgJ2LMa0EqS4iFsfWOw
A40: CHAITRALI YUVRAJ MEHTA | B40: 39 | C40: 19 | E40: 9404825525
...

Sheet Debug_ID_card_data
A1: Name(As per adhar card) | B1: Badge Number | C1: Age | D1: Blood Group | E1: Emergency Contact number | F1: Source | G1: Matched With | H1: Key Used
A2: Aachal Vinod Bhandari | B2: 1 | C2: 15 | D2: B +ve | E2: 7720064326 | F2: Aaradhak | G2: Aachal Vinod Bhandari | H2: aachal bhandari
A3: Aanchal jain | B3: 2 | C3: 26 | D3: B +ve | E3: 9826990266 | F3: Aaradhak | G3: Aanchal jain | H3: aanchal jain
A4: Aangi | B4: 3 | E4: 7405658429 | F4: Raw Data | H4: aangi
A5: Aarna | B5: 4 | E5: 9904082060 | F5: Raw Data | H5: aarna
A6: Aarushi Bhandari | B6: 5 | C6: 16 | E6: 9827637699 | F6: Raw Data | H6: aarushi bhandari
A7: Aashvi chhajed | B7: 6 | C7: 15 | D7: B +ve | E7: 7000496236 | F7: Aaradhak | G7: Aashvi chhajed | H7: aashvi chhajed
A8: Aayushi Jain | B8: 7 | C8: 19 | D8: AB +ve | E8: 6261707675 | F8: Aaradhak | G8: Aayushi Jain | H8: aayushi jain
A9: Aayushi shah | B9: 8 | C9: 25 | D9: B -ve | E9: 9224190392 | F9: Aaradhak | G9: Aayushi Shah | H9: aayushi shah
A10: Abhilasha Jain | B10: 9 | C10: 34 | E10: 7089024861 | F10: Raw Data | H10: abhilasha jain
A11: Additi Solanki | B11: 10 | C11: 23 | D11: B +ve | E11: 9940478564 | F11: Aaradhak | G11: Additi Solanki | H11: additi solanki
A12: Aditi | B12: 11 | E12: 8104916757 | F12: Raw Data | H12: aditi
A13: Aditi Bhandari | B13: 12 | C13: 21 | D13: O +ve | E13: 6260662123 | F13: Aaradhak | G13: Aditi bhandari | H13: aditi bhandari
A14: Aditi jain | B14: 13 | C14: 23 | D14: A +ve | E14: 9324746678 | F14: Aaradhak | G14: Aditi Bharat Jain | H14: aditi jain
A15: Aishvi jain | B15: 14 | C15: 26 | D15: B +ve | E15: 9893618270 | F15: Aaradhak | G15: Aishvi jain | H15: aishvi jain
A16: Akshara Jain | B16: 15 | C16: 16 | E16: 9584175407 | F16: Raw Data | H16: akshara jain
A17: Aksharachopra | B17: 16 | C17: 17 | E17: 8253003710 | F17: Raw Data | H17: aksharachopra
A18: Amisha Saklecha | B18: 17 | C18: 25 | D18: A +ve | E18: 9713410009 | F18: Aaradhak | G18: Amisha Saklecha | H18: amisha saklecha
A19: Amita Mangesh Bora | B19: 18 | C19: 32 | D19: B +ve | E19: 9762808997 | F19: Aaradhak | G19: Amita Mangesh Bora | H19: amita bora
A20: Aneriben Manoj Kumar Shah | B20: 19 | C20: 19 | E20: 9737943472 | F20: Raw Data | H20: aneriben shah
A21: Anuja Romil Shah | B21: 20 | C21: 42 | D21: B +ve | E21: 9825011862 | F21: Aaradhak | G21: Anuja Romil Shah | H21: anuja shah
A22: Anushi Jain | B22: 21 | C22: 24 | D22: O +ve | E22: 9827071761 | F22: Aaradhak | G22: Anushi Jain | H22: anushi jain
A23: Anushka Kataria | B23: 22 | C23: 21 | D23: B +ve | E23: 9425104131 | F23: Aaradhak | G23: Anushka Kataria | H23: anushka kataria
A24: Aradhana jain | B24: 23 | C24: 31 | D24: B +ve | E24: 7999992925 | F24: Aaradhak | G24: Aradhana jain | H24: aradhana jain
A25: Ariha Deep Shah | B25: 24 | C25: 26 | D25: A +ve | E25: 9011096550 | F25: Aaradhak | G25: Ariha Deep Shah | H25: ariha shah
A26: Arpita Jain | B26: 25 | C26: 23 | D26: O +ve | E26: 9179352310 | F26: Aaradhak | G26: Arpita Jain | H26: arpita jain
A27: Arpita vanvat | B27: 26 | C27: 36 | D27: O +ve | E27: 8770483294 | F27: Aaradhak | G27: Arpita vanvat | H27: arpita vanvat
A28: Ashvi Jain | B28: 27 | C28: 18 | D28: AB +ve | E28: 9425068194 | F28: Aaradhak | G28: Ashvi Jain | H28: ashvi jain
A29: Avani Lodha | B29: 28 | C29: 19 | E29: 9424044167 | F29: Raw Data | H29: avani lodha
A30: Avni jain | B30: 29 | C30: 27 | D30: B +ve | E30: 7771906579 | F30: Aaradhak | G30: Avni Jain | H30: avni jain
A31: Ayushi chopra | B31: 30 | C31: 24 | D31: O +ve | E31: 7354054343 | F31: Aaradhak | G31: Ayushi chopra | H31: ayushi chopra
A32: B Ritu kothari | B32: 31 | C32: 28 | D32: O +ve | E32: 9381015186 | F32: Aaradhak | G32: B Ritu kothari | H32: b kothari
A33: Bhaavee Chirag Doshi | B33: 32 | C33: 13 | D33: O +ve | E33: 9552278383 | F33: Aaradhak | G33: Bhaavee Chirag Doshi | H33: bhaavee doshi
A34: Bhakti Jhaveri | B34: 33 | C34: 40 | D34: B +ve | E34: 8369232493 | F34: Aaradhak | G34: Bhakti Jhaveri | H34: bhakti jhaveri
A35: Bhavana | B35: 34 | C35: 33 | E35: 7667643221 | F35: Raw Data | H35: bhavana
A36: Bhavya | B36: 35 | C36: 20 | D36: AB +ve | E36: 8015363385 | F36: Aaradhak | G36: Bhavya | H36: bhavya
A37: Bhumi chatter | B37: 36 | C37: 15 | D37: O +ve | E37: 9584231441 | F37: Aaradhak | G37: Bhumi Chatter | H37: bhumi chatter
A38: Bhumi Umesh Gadiya | B38: 37 | C38: 18 | E38: 7620396824 | F38: Raw Data | H38: bhumi gadiya
A39: Bhumika | B39: 38 | C39: 30 | D39: A +ve | E39: 9561195563 | F39: Aaradhak (first) | G39: Bhumika Jugal Porwal | H39: bhumika
A40: CHAITRALI YUVRAJ MEHTA | B40: 39 | C40: 19 | E40: 9404825525 | F40: Raw Data | H40: chaitrali mehta
...
